2021-04-26 14:25:11.595513: W tensorflow/stream_executor/platform/default/dso_loader.cc:60] Could not load dynamic library 'libcudart.so.11.0'; dlerror: libcudart.so.11.0: cannot open shared object file: No such file or directory; LD_LIBRARY_PATH: /opt/ros/noetic/lib:/opt/ros/noetic/lib/x86_64-linux-gnu
2021-04-26 14:25:11.595672: I tensorflow/stream_executor/cuda/cudart_stub.cc:29] Ignore above cudart dlerror if you do not have a GPU set up on your machine.
Traceback (most recent call last):
  File "rddpg_v2.py", line 7, in <module>
    from rl.rddpg_net_v2 import ActorNetwork, CriticNetwork
  File "/home/shandilya/Desktop/CNS/DDP/src/rl/rddpg_net_v2.py", line 359
    desired_motion, _ z = cell.inputs
                      ^
SyntaxError: invalid syntax
2021-04-26 14:27:26.634374: W tensorflow/stream_executor/platform/default/dso_loader.cc:60] Could not load dynamic library 'libcudart.so.11.0'; dlerror: libcudart.so.11.0: cannot open shared object file: No such file or directory; LD_LIBRARY_PATH: /opt/ros/noetic/lib:/opt/ros/noetic/lib/x86_64-linux-gnu
2021-04-26 14:27:26.634412: I tensorflow/stream_executor/cuda/cudart_stub.cc:29] Ignore above cudart dlerror if you do not have a GPU set up on your machine.
Traceback (most recent call last):
  File "rddpg_v2.py", line 7, in <module>
    from rl.rddpg_net_v2 import ActorNetwork, CriticNetwork
  File "/home/shandilya/Desktop/CNS/DDP/src/rl/rddpg_net_v2.py", line 367
    dtype = tf.dtypes.float32,
    ^
SyntaxError: invalid syntax
2021-04-26 14:29:11.055221: W tensorflow/stream_executor/platform/default/dso_loader.cc:60] Could not load dynamic library 'libcudart.so.11.0'; dlerror: libcudart.so.11.0: cannot open shared object file: No such file or directory; LD_LIBRARY_PATH: /opt/ros/noetic/lib:/opt/ros/noetic/lib/x86_64-linux-gnu
2021-04-26 14:29:11.055257: I tensorflow/stream_executor/cuda/cudart_stub.cc:29] Ignore above cudart dlerror if you do not have a GPU set up on your machine.
Traceback (most recent call last):
  File "rddpg_v2.py", line 7, in <module>
    from rl.rddpg_net_v2 import ActorNetwork, CriticNetwork
  File "/home/shandilya/Desktop/CNS/DDP/src/rl/rddpg_net_v2.py", line 402
    def create_actor_network(self, params, cell = None, \
                                                        ^
IndentationError: unindent does not match any outer indentation level
2021-04-26 14:30:25.376597: W tensorflow/stream_executor/platform/default/dso_loader.cc:60] Could not load dynamic library 'libcudart.so.11.0'; dlerror: libcudart.so.11.0: cannot open shared object file: No such file or directory; LD_LIBRARY_PATH: /opt/ros/noetic/lib:/opt/ros/noetic/lib/x86_64-linux-gnu
2021-04-26 14:30:25.376636: I tensorflow/stream_executor/cuda/cudart_stub.cc:29] Ignore above cudart dlerror if you do not have a GPU set up on your machine.
Traceback (most recent call last):
  File "rddpg_v2.py", line 7, in <module>
    from rl.rddpg_net_v2 import ActorNetwork, CriticNetwork
  File "/home/shandilya/Desktop/CNS/DDP/src/rl/rddpg_net_v2.py", line 430
    dtype = tf.dtypes.float32,
    ^
SyntaxError: invalid syntax
2021-04-26 14:31:13.032626: W tensorflow/stream_executor/platform/default/dso_loader.cc:60] Could not load dynamic library 'libcudart.so.11.0'; dlerror: libcudart.so.11.0: cannot open shared object file: No such file or directory; LD_LIBRARY_PATH: /opt/ros/noetic/lib:/opt/ros/noetic/lib/x86_64-linux-gnu
2021-04-26 14:31:13.032658: I tensorflow/stream_executor/cuda/cudart_stub.cc:29] Ignore above cudart dlerror if you do not have a GPU set up on your machine.
2021-04-26 14:31:17.418578: I tensorflow/compiler/jit/xla_cpu_device.cc:41] Not creating XLA devices, tf_xla_enable_xla_devices not set
2021-04-26 14:31:17.441209: W tensorflow/stream_executor/platform/default/dso_loader.cc:60] Could not load dynamic library 'libcuda.so.1'; dlerror: libcuda.so.1: cannot open shared object file: No such file or directory; LD_LIBRARY_PATH: /opt/ros/noetic/lib:/opt/ros/noetic/lib/x86_64-linux-gnu
2021-04-26 14:31:17.441264: W tensorflow/stream_executor/cuda/cuda_driver.cc:326] failed call to cuInit: UNKNOWN ERROR (303)
2021-04-26 14:31:17.441336: I tensorflow/stream_executor/cuda/cuda_diagnostics.cc:156] kernel driver does not appear to be running on this host (shandilya-notebook): /proc/driver/nvidia/version does not exist
Traceback (most recent call last):
  File "rddpg_v2.py", line 1423, in <module>
    learner = Learner(params, args.experiment, False)
  File "rddpg_v2.py", line 26, in __init__
    self.actor = ActorNetwork(self.params)
  File "/home/shandilya/Desktop/CNS/DDP/src/rl/rddpg_net_v2.py", line 115, in __init__
    train_param_net = train_parma_net, \
NameError: name 'train_parma_net' is not defined
2021-04-26 14:32:15.974663: W tensorflow/stream_executor/platform/default/dso_loader.cc:60] Could not load dynamic library 'libcudart.so.11.0'; dlerror: libcudart.so.11.0: cannot open shared object file: No such file or directory; LD_LIBRARY_PATH: /opt/ros/noetic/lib:/opt/ros/noetic/lib/x86_64-linux-gnu
2021-04-26 14:32:15.974698: I tensorflow/stream_executor/cuda/cudart_stub.cc:29] Ignore above cudart dlerror if you do not have a GPU set up on your machine.
2021-04-26 14:32:19.324564: I tensorflow/compiler/jit/xla_cpu_device.cc:41] Not creating XLA devices, tf_xla_enable_xla_devices not set
2021-04-26 14:32:19.324907: W tensorflow/stream_executor/platform/default/dso_loader.cc:60] Could not load dynamic library 'libcuda.so.1'; dlerror: libcuda.so.1: cannot open shared object file: No such file or directory; LD_LIBRARY_PATH: /opt/ros/noetic/lib:/opt/ros/noetic/lib/x86_64-linux-gnu
2021-04-26 14:32:19.324943: W tensorflow/stream_executor/cuda/cuda_driver.cc:326] failed call to cuInit: UNKNOWN ERROR (303)
2021-04-26 14:32:19.324971: I tensorflow/stream_executor/cuda/cuda_diagnostics.cc:156] kernel driver does not appear to be running on this host (shandilya-notebook): /proc/driver/nvidia/version does not exist
2021-04-26 14:32:19.377991: I tensorflow/core/platform/cpu_feature_guard.cc:142] This TensorFlow binary is optimized with oneAPI Deep Neural Network Library (oneDNN) to use the following CPU instructions in performance-critical operations:  AVX2 FMA
To enable them in other operations, rebuild TensorFlow with the appropriate compiler flags.
2021-04-26 14:32:19.378602: I tensorflow/compiler/jit/xla_gpu_device.cc:99] Not creating XLA devices, tf_xla_enable_xla_devices not set
Traceback (most recent call last):
  File "/home/shandilya/.local/lib/python3.8/site-packages/tensorflow/python/training/py_checkpoint_reader.py", line 95, in NewCheckpointReader
    return CheckpointReader(compat.as_bytes(filepattern))
RuntimeError: Unsuccessful TensorSliceReader constructor: Failed to find any matching files for weights/actor_pretrain/exp52/pretrain_actor/                actor_pretrained_pretrain_actor_52_335.ckpt

During handling of the above exception, another exception occurred:

Traceback (most recent call last):
  File "rddpg_v2.py", line 1423, in <module>
    learner = Learner(params, args.experiment, False)
  File "rddpg_v2.py", line 26, in __init__
    self.actor = ActorNetwork(self.params)
  File "/home/shandilya/Desktop/CNS/DDP/src/rl/rddpg_net_v2.py", line 112, in __init__
    self.model = self.create_actor_network(
  File "/home/shandilya/Desktop/CNS/DDP/src/rl/rddpg_net_v2.py", line 408, in create_actor_network
    cell = self.create_actor_cell(
  File "/home/shandilya/Desktop/CNS/DDP/src/rl/rddpg_net_v2.py", line 358, in create_actor_cell
    cell.load_weights(weights_path)
  File "/home/shandilya/.local/lib/python3.8/site-packages/tensorflow/python/keras/engine/training.py", line 2199, in load_weights
    py_checkpoint_reader.NewCheckpointReader(filepath)
  File "/home/shandilya/.local/lib/python3.8/site-packages/tensorflow/python/training/py_checkpoint_reader.py", line 99, in NewCheckpointReader
    error_translator(e)
  File "/home/shandilya/.local/lib/python3.8/site-packages/tensorflow/python/training/py_checkpoint_reader.py", line 35, in error_translator
    raise errors_impl.NotFoundError(None, None, error_message)
tensorflow.python.framework.errors_impl.NotFoundError: Unsuccessful TensorSliceReader constructor: Failed to find any matching files for weights/actor_pretrain/exp52/pretrain_actor/                actor_pretrained_pretrain_actor_52_335.ckpt
2021-04-26 14:34:04.115184: W tensorflow/stream_executor/platform/default/dso_loader.cc:60] Could not load dynamic library 'libcudart.so.11.0'; dlerror: libcudart.so.11.0: cannot open shared object file: No such file or directory; LD_LIBRARY_PATH: /opt/ros/noetic/lib:/opt/ros/noetic/lib/x86_64-linux-gnu
2021-04-26 14:34:04.115221: I tensorflow/stream_executor/cuda/cudart_stub.cc:29] Ignore above cudart dlerror if you do not have a GPU set up on your machine.
2021-04-26 14:34:07.522020: I tensorflow/compiler/jit/xla_cpu_device.cc:41] Not creating XLA devices, tf_xla_enable_xla_devices not set
2021-04-26 14:34:07.522365: W tensorflow/stream_executor/platform/default/dso_loader.cc:60] Could not load dynamic library 'libcuda.so.1'; dlerror: libcuda.so.1: cannot open shared object file: No such file or directory; LD_LIBRARY_PATH: /opt/ros/noetic/lib:/opt/ros/noetic/lib/x86_64-linux-gnu
2021-04-26 14:34:07.522414: W tensorflow/stream_executor/cuda/cuda_driver.cc:326] failed call to cuInit: UNKNOWN ERROR (303)
2021-04-26 14:34:07.522444: I tensorflow/stream_executor/cuda/cuda_diagnostics.cc:156] kernel driver does not appear to be running on this host (shandilya-notebook): /proc/driver/nvidia/version does not exist
2021-04-26 14:34:07.543739: I tensorflow/core/platform/cpu_feature_guard.cc:142] This TensorFlow binary is optimized with oneAPI Deep Neural Network Library (oneDNN) to use the following CPU instructions in performance-critical operations:  AVX2 FMA
To enable them in other operations, rebuild TensorFlow with the appropriate compiler flags.
2021-04-26 14:34:07.544047: I tensorflow/compiler/jit/xla_gpu_device.cc:99] Not creating XLA devices, tf_xla_enable_xla_devices not set
Traceback (most recent call last):
  File "rddpg_v2.py", line 1423, in <module>
    learner = Learner(params, args.experiment, False)
  File "rddpg_v2.py", line 26, in __init__
    self.actor = ActorNetwork(self.params)
  File "/home/shandilya/Desktop/CNS/DDP/src/rl/rddpg_net_v2.py", line 111, in __init__
    self.model = self.create_actor_network(
  File "/home/shandilya/Desktop/CNS/DDP/src/rl/rddpg_net_v2.py", line 407, in create_actor_network
    cell = self.create_actor_cell(
  File "/home/shandilya/Desktop/CNS/DDP/src/rl/rddpg_net_v2.py", line 370, in create_actor_cell
    units = units_omega[0],
NameError: name 'units_omega' is not defined
2021-04-26 14:34:56.267571: W tensorflow/stream_executor/platform/default/dso_loader.cc:60] Could not load dynamic library 'libcudart.so.11.0'; dlerror: libcudart.so.11.0: cannot open shared object file: No such file or directory; LD_LIBRARY_PATH: /opt/ros/noetic/lib:/opt/ros/noetic/lib/x86_64-linux-gnu
2021-04-26 14:34:56.267617: I tensorflow/stream_executor/cuda/cudart_stub.cc:29] Ignore above cudart dlerror if you do not have a GPU set up on your machine.
2021-04-26 14:35:00.134017: I tensorflow/compiler/jit/xla_cpu_device.cc:41] Not creating XLA devices, tf_xla_enable_xla_devices not set
2021-04-26 14:35:00.134377: W tensorflow/stream_executor/platform/default/dso_loader.cc:60] Could not load dynamic library 'libcuda.so.1'; dlerror: libcuda.so.1: cannot open shared object file: No such file or directory; LD_LIBRARY_PATH: /opt/ros/noetic/lib:/opt/ros/noetic/lib/x86_64-linux-gnu
2021-04-26 14:35:00.134409: W tensorflow/stream_executor/cuda/cuda_driver.cc:326] failed call to cuInit: UNKNOWN ERROR (303)
2021-04-26 14:35:00.134433: I tensorflow/stream_executor/cuda/cuda_diagnostics.cc:156] kernel driver does not appear to be running on this host (shandilya-notebook): /proc/driver/nvidia/version does not exist
2021-04-26 14:35:00.153324: I tensorflow/core/platform/cpu_feature_guard.cc:142] This TensorFlow binary is optimized with oneAPI Deep Neural Network Library (oneDNN) to use the following CPU instructions in performance-critical operations:  AVX2 FMA
To enable them in other operations, rebuild TensorFlow with the appropriate compiler flags.
2021-04-26 14:35:00.153909: I tensorflow/compiler/jit/xla_gpu_device.cc:99] Not creating XLA devices, tf_xla_enable_xla_devices not set
Traceback (most recent call last):
  File "rddpg_v2.py", line 1423, in <module>
    learner = Learner(params, args.experiment, False)
  File "rddpg_v2.py", line 26, in __init__
    self.actor = ActorNetwork(self.params)
  File "/home/shandilya/Desktop/CNS/DDP/src/rl/rddpg_net_v2.py", line 111, in __init__
    self.model = self.create_actor_network(
  File "/home/shandilya/Desktop/CNS/DDP/src/rl/rddpg_net_v2.py", line 407, in create_actor_network
    cell = self.create_actor_cell(
  File "/home/shandilya/Desktop/CNS/DDP/src/rl/rddpg_net_v2.py", line 380, in create_actor_cell
    activation = activation_omega,
NameError: name 'activation_omega' is not defined
2021-04-26 14:36:50.402292: W tensorflow/stream_executor/platform/default/dso_loader.cc:60] Could not load dynamic library 'libcudart.so.11.0'; dlerror: libcudart.so.11.0: cannot open shared object file: No such file or directory; LD_LIBRARY_PATH: /opt/ros/noetic/lib:/opt/ros/noetic/lib/x86_64-linux-gnu
2021-04-26 14:36:50.402328: I tensorflow/stream_executor/cuda/cudart_stub.cc:29] Ignore above cudart dlerror if you do not have a GPU set up on your machine.
2021-04-26 14:36:53.970896: I tensorflow/compiler/jit/xla_cpu_device.cc:41] Not creating XLA devices, tf_xla_enable_xla_devices not set
2021-04-26 14:36:53.971405: W tensorflow/stream_executor/platform/default/dso_loader.cc:60] Could not load dynamic library 'libcuda.so.1'; dlerror: libcuda.so.1: cannot open shared object file: No such file or directory; LD_LIBRARY_PATH: /opt/ros/noetic/lib:/opt/ros/noetic/lib/x86_64-linux-gnu
2021-04-26 14:36:53.971571: W tensorflow/stream_executor/cuda/cuda_driver.cc:326] failed call to cuInit: UNKNOWN ERROR (303)
2021-04-26 14:36:53.971716: I tensorflow/stream_executor/cuda/cuda_diagnostics.cc:156] kernel driver does not appear to be running on this host (shandilya-notebook): /proc/driver/nvidia/version does not exist
2021-04-26 14:36:53.992279: I tensorflow/core/platform/cpu_feature_guard.cc:142] This TensorFlow binary is optimized with oneAPI Deep Neural Network Library (oneDNN) to use the following CPU instructions in performance-critical operations:  AVX2 FMA
To enable them in other operations, rebuild TensorFlow with the appropriate compiler flags.
2021-04-26 14:36:53.992860: I tensorflow/compiler/jit/xla_gpu_device.cc:99] Not creating XLA devices, tf_xla_enable_xla_devices not set
Traceback (most recent call last):
  File "rddpg_v2.py", line 1423, in <module>
    learner = Learner(params, args.experiment, False)
  File "rddpg_v2.py", line 26, in __init__
    self.actor = ActorNetwork(self.params)
  File "/home/shandilya/Desktop/CNS/DDP/src/rl/rddpg_net_v2.py", line 111, in __init__
    self.model = self.create_actor_network(
  File "/home/shandilya/Desktop/CNS/DDP/src/rl/rddpg_net_v2.py", line 407, in create_actor_network
    cell = self.create_actor_cell(
  File "/home/shandilya/Desktop/CNS/DDP/src/rl/rddpg_net_v2.py", line 386, in create_actor_cell
    x_R, state = gru(robo_state, robot_enc_state)
NameError: name 'robo_state' is not defined
2021-04-26 14:38:14.482687: W tensorflow/stream_executor/platform/default/dso_loader.cc:60] Could not load dynamic library 'libcudart.so.11.0'; dlerror: libcudart.so.11.0: cannot open shared object file: No such file or directory; LD_LIBRARY_PATH: /opt/ros/noetic/lib:/opt/ros/noetic/lib/x86_64-linux-gnu
2021-04-26 14:38:14.482720: I tensorflow/stream_executor/cuda/cudart_stub.cc:29] Ignore above cudart dlerror if you do not have a GPU set up on your machine.
2021-04-26 14:38:18.035523: I tensorflow/compiler/jit/xla_cpu_device.cc:41] Not creating XLA devices, tf_xla_enable_xla_devices not set
2021-04-26 14:38:18.035874: W tensorflow/stream_executor/platform/default/dso_loader.cc:60] Could not load dynamic library 'libcuda.so.1'; dlerror: libcuda.so.1: cannot open shared object file: No such file or directory; LD_LIBRARY_PATH: /opt/ros/noetic/lib:/opt/ros/noetic/lib/x86_64-linux-gnu
2021-04-26 14:38:18.035900: W tensorflow/stream_executor/cuda/cuda_driver.cc:326] failed call to cuInit: UNKNOWN ERROR (303)
2021-04-26 14:38:18.035940: I tensorflow/stream_executor/cuda/cuda_diagnostics.cc:156] kernel driver does not appear to be running on this host (shandilya-notebook): /proc/driver/nvidia/version does not exist
2021-04-26 14:38:18.053910: I tensorflow/core/platform/cpu_feature_guard.cc:142] This TensorFlow binary is optimized with oneAPI Deep Neural Network Library (oneDNN) to use the following CPU instructions in performance-critical operations:  AVX2 FMA
To enable them in other operations, rebuild TensorFlow with the appropriate compiler flags.
2021-04-26 14:38:18.054157: I tensorflow/compiler/jit/xla_gpu_device.cc:99] Not creating XLA devices, tf_xla_enable_xla_devices not set
Traceback (most recent call last):
  File "/home/shandilya/.local/lib/python3.8/site-packages/tensorflow/python/framework/ops.py", line 1853, in _create_c_op
    c_op = pywrap_tf_session.TF_FinishOperation(op_desc)
tensorflow.python.framework.errors_impl.InvalidArgumentError: Dimensions must be equal, but are 120 and 45 for '{{node robot_state_enc_gru/MatMul_1}} = MatMul[T=DT_FLOAT, transpose_a=false, transpose_b=false](Placeholder_1, robot_state_enc_gru/MatMul_1/ReadVariableOp)' with input shapes: [?,120], [45,135].

During handling of the above exception, another exception occurred:

Traceback (most recent call last):
  File "rddpg_v2.py", line 1423, in <module>
    learner = Learner(params, args.experiment, False)
  File "rddpg_v2.py", line 26, in __init__
    self.actor = ActorNetwork(self.params)
  File "/home/shandilya/Desktop/CNS/DDP/src/rl/rddpg_net_v2.py", line 111, in __init__
    self.model = self.create_actor_network(
  File "/home/shandilya/Desktop/CNS/DDP/src/rl/rddpg_net_v2.py", line 407, in create_actor_network
    cell = self.create_actor_cell(
  File "/home/shandilya/Desktop/CNS/DDP/src/rl/rddpg_net_v2.py", line 386, in create_actor_cell
    x_R, state = gru(robot_state, robot_enc_state)
  File "/home/shandilya/.local/lib/python3.8/site-packages/tensorflow/python/keras/engine/base_layer.py", line 951, in __call__
    return self._functional_construction_call(inputs, args, kwargs,
  File "/home/shandilya/.local/lib/python3.8/site-packages/tensorflow/python/keras/engine/base_layer.py", line 1090, in _functional_construction_call
    outputs = self._keras_tensor_symbolic_call(
  File "/home/shandilya/.local/lib/python3.8/site-packages/tensorflow/python/keras/engine/base_layer.py", line 822, in _keras_tensor_symbolic_call
    return self._infer_output_signature(inputs, args, kwargs, input_masks)
  File "/home/shandilya/.local/lib/python3.8/site-packages/tensorflow/python/keras/engine/base_layer.py", line 863, in _infer_output_signature
    outputs = call_fn(inputs, *args, **kwargs)
  File "/home/shandilya/.local/lib/python3.8/site-packages/tensorflow/python/keras/layers/recurrent.py", line 1894, in call
    matrix_inner = K.dot(h_tm1, self.recurrent_kernel)
  File "/home/shandilya/.local/lib/python3.8/site-packages/tensorflow/python/util/dispatch.py", line 201, in wrapper
    return target(*args, **kwargs)
  File "/home/shandilya/.local/lib/python3.8/site-packages/tensorflow/python/keras/backend.py", line 1898, in dot
    out = math_ops.matmul(x, y)
  File "/home/shandilya/.local/lib/python3.8/site-packages/tensorflow/python/util/dispatch.py", line 201, in wrapper
    return target(*args, **kwargs)
  File "/home/shandilya/.local/lib/python3.8/site-packages/tensorflow/python/ops/math_ops.py", line 3314, in matmul
    return gen_math_ops.mat_mul(
  File "/home/shandilya/.local/lib/python3.8/site-packages/tensorflow/python/ops/gen_math_ops.py", line 5548, in mat_mul
    _, _, _op, _outputs = _op_def_library._apply_op_helper(
  File "/home/shandilya/.local/lib/python3.8/site-packages/tensorflow/python/framework/op_def_library.py", line 748, in _apply_op_helper
    op = g._create_op_internal(op_type_name, inputs, dtypes=None,
  File "/home/shandilya/.local/lib/python3.8/site-packages/tensorflow/python/framework/func_graph.py", line 590, in _create_op_internal
    return super(FuncGraph, self)._create_op_internal(  # pylint: disable=protected-access
  File "/home/shandilya/.local/lib/python3.8/site-packages/tensorflow/python/framework/ops.py", line 3528, in _create_op_internal
    ret = Operation(
  File "/home/shandilya/.local/lib/python3.8/site-packages/tensorflow/python/framework/ops.py", line 2015, in __init__
    self._c_op = _create_c_op(self._graph, node_def, inputs,
  File "/home/shandilya/.local/lib/python3.8/site-packages/tensorflow/python/framework/ops.py", line 1856, in _create_c_op
    raise ValueError(str(e))
ValueError: Dimensions must be equal, but are 120 and 45 for '{{node robot_state_enc_gru/MatMul_1}} = MatMul[T=DT_FLOAT, transpose_a=false, transpose_b=false](Placeholder_1, robot_state_enc_gru/MatMul_1/ReadVariableOp)' with input shapes: [?,120], [45,135].
2021-04-26 14:41:42.329348: W tensorflow/stream_executor/platform/default/dso_loader.cc:60] Could not load dynamic library 'libcudart.so.11.0'; dlerror: libcudart.so.11.0: cannot open shared object file: No such file or directory; LD_LIBRARY_PATH: /opt/ros/noetic/lib:/opt/ros/noetic/lib/x86_64-linux-gnu
2021-04-26 14:41:42.329383: I tensorflow/stream_executor/cuda/cudart_stub.cc:29] Ignore above cudart dlerror if you do not have a GPU set up on your machine.
2021-04-26 14:41:45.768830: I tensorflow/compiler/jit/xla_cpu_device.cc:41] Not creating XLA devices, tf_xla_enable_xla_devices not set
2021-04-26 14:41:45.769121: W tensorflow/stream_executor/platform/default/dso_loader.cc:60] Could not load dynamic library 'libcuda.so.1'; dlerror: libcuda.so.1: cannot open shared object file: No such file or directory; LD_LIBRARY_PATH: /opt/ros/noetic/lib:/opt/ros/noetic/lib/x86_64-linux-gnu
2021-04-26 14:41:45.769140: W tensorflow/stream_executor/cuda/cuda_driver.cc:326] failed call to cuInit: UNKNOWN ERROR (303)
2021-04-26 14:41:45.769159: I tensorflow/stream_executor/cuda/cuda_diagnostics.cc:156] kernel driver does not appear to be running on this host (shandilya-notebook): /proc/driver/nvidia/version does not exist
2021-04-26 14:41:45.789091: I tensorflow/core/platform/cpu_feature_guard.cc:142] This TensorFlow binary is optimized with oneAPI Deep Neural Network Library (oneDNN) to use the following CPU instructions in performance-critical operations:  AVX2 FMA
To enable them in other operations, rebuild TensorFlow with the appropriate compiler flags.
2021-04-26 14:41:45.789398: I tensorflow/compiler/jit/xla_gpu_device.cc:99] Not creating XLA devices, tf_xla_enable_xla_devices not set
Traceback (most recent call last):
  File "rddpg_v2.py", line 1423, in <module>
    learner = Learner(params, args.experiment, False)
  File "rddpg_v2.py", line 26, in __init__
    self.actor = ActorNetwork(self.params)
  File "/home/shandilya/Desktop/CNS/DDP/src/rl/rddpg_net_v2.py", line 111, in __init__
    self.model = self.create_actor_network(
  File "/home/shandilya/Desktop/CNS/DDP/src/rl/rddpg_net_v2.py", line 407, in create_actor_network
    cell = self.create_actor_cell(
  File "/home/shandilya/Desktop/CNS/DDP/src/rl/rddpg_net_v2.py", line 395, in create_actor_cell
    desired_motion, robot_state, z, robot_state_enc
NameError: name 'robot_state_enc' is not defined
2021-04-26 14:43:32.414001: W tensorflow/stream_executor/platform/default/dso_loader.cc:60] Could not load dynamic library 'libcudart.so.11.0'; dlerror: libcudart.so.11.0: cannot open shared object file: No such file or directory; LD_LIBRARY_PATH: /opt/ros/noetic/lib:/opt/ros/noetic/lib/x86_64-linux-gnu
2021-04-26 14:43:32.414037: I tensorflow/stream_executor/cuda/cudart_stub.cc:29] Ignore above cudart dlerror if you do not have a GPU set up on your machine.
2021-04-26 14:43:35.883082: I tensorflow/compiler/jit/xla_cpu_device.cc:41] Not creating XLA devices, tf_xla_enable_xla_devices not set
2021-04-26 14:43:35.883656: W tensorflow/stream_executor/platform/default/dso_loader.cc:60] Could not load dynamic library 'libcuda.so.1'; dlerror: libcuda.so.1: cannot open shared object file: No such file or directory; LD_LIBRARY_PATH: /opt/ros/noetic/lib:/opt/ros/noetic/lib/x86_64-linux-gnu
2021-04-26 14:43:35.883835: W tensorflow/stream_executor/cuda/cuda_driver.cc:326] failed call to cuInit: UNKNOWN ERROR (303)
2021-04-26 14:43:35.883981: I tensorflow/stream_executor/cuda/cuda_diagnostics.cc:156] kernel driver does not appear to be running on this host (shandilya-notebook): /proc/driver/nvidia/version does not exist
2021-04-26 14:43:35.905066: I tensorflow/core/platform/cpu_feature_guard.cc:142] This TensorFlow binary is optimized with oneAPI Deep Neural Network Library (oneDNN) to use the following CPU instructions in performance-critical operations:  AVX2 FMA
To enable them in other operations, rebuild TensorFlow with the appropriate compiler flags.
2021-04-26 14:43:35.905634: I tensorflow/compiler/jit/xla_gpu_device.cc:99] Not creating XLA devices, tf_xla_enable_xla_devices not set
Traceback (most recent call last):
  File "rddpg_v2.py", line 1423, in <module>
    learner = Learner(params, args.experiment, False)
  File "rddpg_v2.py", line 26, in __init__
    self.actor = ActorNetwork(self.params)
  File "/home/shandilya/Desktop/CNS/DDP/src/rl/rddpg_net_v2.py", line 111, in __init__
    self.model = self.create_actor_network(
  File "/home/shandilya/Desktop/CNS/DDP/src/rl/rddpg_net_v2.py", line 450, in create_actor_network
    [actions, _, _, _, _], [Z, state] = rnn([
  File "/home/shandilya/.local/lib/python3.8/site-packages/tensorflow/python/keras/engine/base_layer.py", line 951, in __call__
    return self._functional_construction_call(inputs, args, kwargs,
  File "/home/shandilya/.local/lib/python3.8/site-packages/tensorflow/python/keras/engine/base_layer.py", line 1090, in _functional_construction_call
    outputs = self._keras_tensor_symbolic_call(
  File "/home/shandilya/.local/lib/python3.8/site-packages/tensorflow/python/keras/engine/base_layer.py", line 822, in _keras_tensor_symbolic_call
    return self._infer_output_signature(inputs, args, kwargs, input_masks)
  File "/home/shandilya/.local/lib/python3.8/site-packages/tensorflow/python/keras/engine/base_layer.py", line 863, in _infer_output_signature
    outputs = call_fn(inputs, *args, **kwargs)
  File "/home/shandilya/.local/lib/python3.8/site-packages/tensorflow/python/autograph/impl/api.py", line 670, in wrapper
    raise e.ag_error_metadata.to_exception(e)
ValueError: in user code:

    /home/shandilya/Desktop/CNS/DDP/src/rl/rddpg_net_v2.py:75 body  *
        rnn_out = self.rnn_cell(rnn_inp)
    /home/shandilya/.local/lib/python3.8/site-packages/tensorflow/python/keras/engine/base_layer.py:998 __call__  **
        input_spec.assert_input_compatibility(self.input_spec, inputs, self.name)
    /home/shandilya/.local/lib/python3.8/site-packages/tensorflow/python/keras/engine/input_spec.py:271 assert_input_compatibility
        raise ValueError('Input ' + str(input_index) +

    ValueError: Input 2 is incompatible with layer model: expected shape=(None, 60), found shape=(None, 120)

